# Promise

## 为什么需要Promise

有了Promise对象，就可以将异步操作以同步的流程表达出来，避免的层层嵌套的回调函数。

Promise缺点：

1. 无法取消，一旦新建他就会立即执行，无法中途取消。
2. 如果不设置回调函数，Promise内部抛出的错误，不会反应的外部。
3. 当处于pending状态时，无法得知目前进展到哪一个阶段。

## Promise对象的特点

1. 对象的状态不受外界影响。

   > `Promise`对象代表一个异步操作, 有三种状态，
   >
   > - `pending`（进行中）
   > - `fulfilled`（已成功）
   > - `rejected`（已失败）

2. 一旦状态改变，就不会在变，任何时候都可以得到这个结果。

   1. `pending`变为`fulfilled`
   2. `pending`变为`rejected`

## 基本用法

ES6 规定，`Promise`对象是一个构造函数，用来生成`Promise`实例。

上代码：

```js
const promise = new Promise(function(resolve, reject) {
  // ... some code

  if (/* 异步操作成功 */){
    resolve(value);
  } else {
    reject(error);
  }
});
```

`Promise`构造函数接受一个函数作为参数，该函数的两个参数分别是`resolve`和`reject`。它们是两个函数，由 JavaScript 引擎提供，不用自己部署。

- `resolve`函数的作用是，将`Promise`对象的状态从“未完成”变为“成功”（即从 pending 变为 resolved），在异步操作成功时调用，并将异步操作的结果，作为参数传递出去；
- `reject`函数的作用是，将`Promise`对象的状态从“未完成”变为“失败”（即从 pending 变为 rejected），在异步操作失败时调用，并将异步操作报出的错误，作为参数传递出去。

`Promise`实例生成以后，可以用`then`方法分别指定`resolved`状态和`rejected`状态的回调函数。

```js
promise.then(function(value) {
  // success
}, function(error) {
  // failure
});
```

`then`方法可以接受两个回调函数作为参数:

- 第一个回调函数是`Promise`对象的状态变为`resolved`时调用
- 第二个回调函数是`Promise`对象的状态变为`rejected`时调用

> 其中，第二个函数是可选的，不一定要提供。这两个函数都接受`Promise`对象传出的值作为参数。

`Promise`对象实现的 Ajax 操作:

```js
const getJSON = function(url) {
  const promise = new Promise(function(resolve, reject){
    const handler = function() {
      if (this.readyState !== 4) {
        return;
      }
      if (this.status === 200) {
        resolve(this.response);
      } else {
        reject(new Error(this.statusText));
      }
    };
    const client = new XMLHttpRequest();
    client.open("GET", url);
    client.onreadystatechange = handler;
    client.responseType = "json";
    client.setRequestHeader("Accept", "application/json");
    client.send();

  });

  return promise;
};

getJSON("/posts.json").then(function(json) {
  console.log('Contents: ' + json);
}, function(error) {
  console.error('出错了', error);
});
```

上面代码中，`getJSON`是对 XMLHttpRequest 对象的封装，用于发出一个针对 JSON 数据的 HTTP 请求，并且返回一个`Promise`对象。需要注意的是，在`getJSON`内部，`resolve`函数和`reject`函数调用时，都带有参数。

如果调用`resolve`函数和`reject`函数时带有参数，那么它们的参数会被传递给回调函数。`reject`函数的参数通常是`Error`对象的实例，表示抛出的错误；`resolve`函数的参数除了正常的值以外，还可能是另一个 Promise 实例，比如像下面这样。

```js
const p1 = new Promise(function (resolve, reject) {
  setTimeout(() => reject(new Error('fail')), 3000)
})

const p2 = new Promise(function (resolve, reject) {
  setTimeout(() => resolve(p1), 1000)
})

p2
  .then(result => console.log(result))
  .catch(error => console.log(error))
// Error: fail
```

上面代码中，`p1`是一个 Promise，3 秒之后变为`rejected`。`p2`的状态在 1 秒之后改变，`resolve`方法返回的是`p1`。由于`p2`返回的是另一个 Promise，导致`p2`自己的状态无效了，由`p1`的状态决定`p2`的状态。所以，后面的`then`语句都变成针对后者（`p1`）。又过了 2 秒，`p1`变为`rejected`，导致触发`catch`方法指定的回调函数。

注意，调用`resolve`或`reject`并不会终结 Promise 的参数函数的执行。

```javascript
new Promise((resolve, reject) => {
  resolve(1);
  console.log(2);
}).then(r => {
  console.log(r);
});
// 2
// 1
```

上面代码中，调用`resolve(1)`以后，后面的`console.log(2)`还是会执行，并且会首先打印出来。这是因为立即 resolved 的 Promise 是在本轮事件循环的末尾执行，总是晚于本轮循环的同步任务。

一般来说，调用`resolve`或`reject`以后，Promise 的使命就完成了，后继操作应该放到`then`方法里面，而不应该直接写在`resolve`或`reject`的后面。所以，最好在它们前面加上`return`语句，这样就不会有意外。

```javascript
new Promise((resolve, reject) => {
  return resolve(1);
  // 后面的语句不会执行
  console.log(2);
})
```

### then

>  Promise 实例具有`then`方法，也就是说，`then`方法是定义在原型对象`Promise.prototype`上的。

作用：为 Promise 实例添加状态改变时的回调函数。前面说过，`then`方法的第一个参数是`resolved`状态的回调函数，第二个参数（可选）是`rejected`状态的回调函数。

`then`方法返回的是一个新的`Promise`实例（注意，不是原来那个`Promise`实例）。因此可以采用链式写法，即`then`方法后面再调用另一个`then`方法。

```javascript
getJSON("/posts.json").then(function(json) {
  return json.post;
}).then(function(post) {
  // ...
});
```

上面的代码使用`then`方法，依次指定了两个回调函数。第一个回调函数完成以后，会将返回结果作为参数，传入第二个回调函数。

采用链式的`then`，可以指定一组按照次序调用的回调函数。这时，前一个回调函数，有可能返回的还是一个`Promise`对象（即有异步操作），这时后一个回调函数，就会等待该`Promise`对象的状态发生变化，才会被调用。

```javascript
getJSON("/post/1.json").then(function(post) {
  return getJSON(post.commentURL);
}).then(function funcA(comments) {
  console.log("resolved: ", comments);
}, function funcB(err){
  console.log("rejected: ", err);
});
```

上面代码中，第一个`then`方法指定的回调函数，返回的是另一个`Promise`对象。这时，第二个`then`方法指定的回调函数，就会等待这个新的`Promise`对象状态发生变化。如果变为`resolved`，就调用`funcA`，如果状态变为`rejected`，就调用`funcB`。

### catch

> catch方法也是定义在原型对象`Promise.prototype`上的

`Promise.prototype.catch`方法是`.then(null, rejection)`或`.then(undefined, rejection)`的别名，用于指定发生错误时的回调函数。

```javascript
getJSON('/posts.json').then(function(posts) {
  // ...
}).catch(function(error) {
  // 处理 getJSON 和 前一个回调函数运行时发生的错误
  console.log('发生错误！', error);
});
```

上面代码中，`getJSON`方法返回一个 Promise 对象，如果该对象状态变为`resolved`，则会调用`then`方法指定的回调函数；如果异步操作抛出错误，状态就会变为`rejected`，就会调用`catch`方法指定的回调函数，处理这个错误。另外，`then`方法指定的回调函数，如果运行中抛出错误，也会被`catch`方法捕获。

看下面例子：

```javascript
// 写法一
const promise = new Promise(function(resolve, reject) {
  throw new Error('test');
});
promise.catch(function(error) {
  console.log(error);
});

// 写法二
const promise = new Promise(function(resolve, reject) {
  try {
    throw new Error('test');
  } catch(e) {
    reject(e);
  }
});
promise.catch(function(error) {
  console.log(error);
});

// 写法三
const promise = new Promise(function(resolve, reject) {
  reject(new Error('test'));
});
promise.catch(function(error) {
  console.log(error);
});
```

上面三种写法是等价的，通过比较发现，`reject`方法的作用，等同于抛出错误。

如果 Promise 状态已经变成`resolved`，再抛出错误是无效的。

```javascript
const promise = new Promise(function(resolve, reject) {
  resolve('ok');
  throw new Error('test');
});
promise
  .then(function(value) { console.log(value) })
  .catch(function(error) { console.log(error) });
// ok
```

上面代码中，Promise 在`resolve`语句后面，再抛出错误，不会被捕获，等于没有抛出。**因为 Promise 的状态一旦改变，就永久保持该状态，不会再变了**。

Promise 对象的错误具有“**冒泡**”性质，**会一直向后传递**，直到被**捕获为止**。也就是说，错误总是会被下一个`catch`语句捕获。

```javascript
getJSON('/post/1.json').then(function(post) {
  return getJSON(post.commentURL);
}).then(function(comments) {
  // some code
}).catch(function(error) {
  // 处理前面三个Promise产生的错误
});
```

上面代码中，一共有三个 Promise 对象：一个由`getJSON`产生，两个由`then`产生。它们之中任何一个抛出的错误，都会被最后一个`catch`捕获。

一般来说，不要在`then`方法里面定义 Reject 状态的回调函数（即`then`的第二个参数），总是使用`catch`方法。

```javascript
// bad
promise
  .then(function(data) {
    // success
  }, function(err) {
    // error
  });

// good
promise
  .then(function(data) { //cb
    // success
  })
  .catch(function(err) {
    // error
  });
```

上面代码中，第二种写法要好于第一种写法，理由是第二种写法可以捕获前面`then`方法执行中的错误，也更接近同步的写法（`try/catch`）。因此，建议总是使用`catch`方法，而不使用`then`方法的第二个参数。

跟传统的`try/catch`代码块不同的是，如果没有使用`catch`方法指定错误处理的回调函数，Promise 对象抛出的错误不会传递到外层代码，即不会有任何反应。

```javascript
const someAsyncThing = function() {
  return new Promise(function(resolve, reject) {
    // 下面一行会报错，因为x没有声明
    resolve(x + 2);
  });
};

someAsyncThing().then(function() {
  console.log('everything is great');
});

setTimeout(() => { console.log(123) }, 2000);
// Uncaught (in promise) ReferenceError: x is not defined
// 123
```

上面代码中，`someAsyncThing`函数产生的 Promise 对象，内部有语法错误。浏览器运行到这一行，会打印出错误提示`ReferenceError: x is not defined`，但是不会退出进程、终止脚本执行，2 秒之后还是会输出`123`。这就是说，Promise 内部的错误不会影响到 Promise 外部的代码，通俗的说法就是“**Promise 会吃掉错误**”。

一般总是建议，Promise 对象后面要跟`catch`方法，这样可以处理 Promise 内部发生的错误。

### finally

> finally方法也是定义在原型对象`Promise.prototype`上的

`finally`方法用于指定不管 Promise 对象最后状态如何，都会执行的操作。该方法是 ES2018 引入标准的。

```javascript
promise
.then(result => {···})
.catch(error => {···})
.finally(() => {···});
```

上面代码中，不管`promise`最后的状态，在执行完`then`或`catch`指定的回调函数以后，都会执行`finally`方法指定的回调函数。

`finally`方法的回调函数不接受任何参数，这意味着没有办法知道，前面的 Promise 状态到底是`fulfilled`还是`rejected`。这表明，`finally`方法里面的操作，应该是与状态无关的，不依赖于 Promise 的执行结果。

`finally`本质上是`then`方法的特例。

```javascript
promise
.finally(() => {
  // 语句
});

// 等同于
promise
.then(
  result => {
    // 语句
    return result;
  },
  error => {
    // 语句
    throw error;
  }
);
```

上面代码中，如果不使用`finally`方法，同样的语句需要为成功和失败两种情况各写一次。有了`finally`方法，则只需要写一次。

它的实现也很简单。

```javascript
Promise.prototype.finally = function (callback) {
  let P = this.constructor;
  return this.then(
    value  => P.resolve(callback()).then(() => value),
    reason => P.resolve(callback()).then(() => { throw reason })
  );
};
```

上面代码中，不管前面的 Promise 是`fulfilled`还是`rejected`，都会执行回调函数`callback`。

### Promise.all()

`Promise.all`方法用于将多个 Promise 实例，包装成一个新的 Promise 实例。

```javascript
const p = Promise.all([p1, p2, p3]);
```

`p`的状态由`p1`、`p2`、`p3`决定，分成两种情况:

（1）只有`p1`、`p2`、`p3`的状态都变成`fulfilled`，`p`的状态才会变成`fulfilled`，此时`p1`、`p2`、`p3`的返回值组成一个数组，传递给`p`的回调函数。

（2）只要`p1`、`p2`、`p3`之中有一个被`rejected`，`p`的状态就变成`rejected`，此时第一个被`reject`的实例的返回值，会传递给`p`的回调函数。

**注意**，如果作为参数的 Promise 实例，自己定义了`catch`方法，那么它一旦被`rejected`，并不会触发`Promise.all()`的`catch`方法。

```javascript
const p1 = new Promise((resolve, reject) => {
  resolve('hello');
})
.then(result => result)
.catch(e => e);

const p2 = new Promise((resolve, reject) => {
  throw new Error('报错了');
})
.then(result => result)
.catch(e => e);

Promise.all([p1, p2])
.then(result => console.log(result))
.catch(e => console.log(e));
// ["hello", Error: 报错了]
```

上面代码中，`p1`会`resolved`，`p2`首先会`rejected`，但是`p2`有自己的`catch`方法，该方法返回的是一个新的 Promise 实例，`p2`指向的实际上是这个实例。该实例执行完`catch`方法后，也会变成`resolved`，导致`Promise.all()`方法参数里面的两个实例都会`resolved`，因此会调用`then`方法指定的回调函数，而不会调用`catch`方法指定的回调函数。

如果`p2`没有自己的`catch`方法，就会调用`Promise.all()`的`catch`方法。

```javascript
const p1 = new Promise((resolve, reject) => {
  resolve('hello');
})
.then(result => result);

const p2 = new Promise((resolve, reject) => {
  throw new Error('报错了');
})
.then(result => result);

Promise.all([p1, p2])
.then(result => console.log(result))
.catch(e => console.log(e));
// Error: 报错了
```

### Promise.race()

`Promise.race`方法同样是将多个 Promise 实例，包装成一个新的 Promise 实例。

```javascript
const p = Promise.race([p1, p2, p3]);
```

上面代码中，只要`p1`、`p2`、`p3`之中有一个实例**率先**改变状态，`p`的状态就跟着改变。那个率先改变的 Promise 实例的返回值，就传递给`p`的回调函数。

### Promise.resolve()

作用：将现有对象转为 Promise 对象

`Promise.resolve`等价于下面的写法。

```javascript
Promise.resolve('foo')
// 等价于
new Promise(resolve => resolve('foo'))
```

`Promise.resolve`方法的参数分成四种情况：

1. 参数是一个Promise实例

   > 原封不动返回传入的实例

2. 参数是一个thenable对象

   > 将这个对象转为 Promise 对象，然后就立即执行`thenable`对象的`then`方法

   ```js
   let thenable = {
     then: function(resolve, reject) {
       resolve(42);
     }
   };
   
   let p1 = Promise.resolve(thenable);
   p1.then(function(value) {
     console.log(value);  // 42
   });
   ```

   

3. 参数不是一个具有then方法的对象，或根本就不是对象

   > 返回一个新的 Promise 对象，状态为`resolved`

   ```javascript
   const p = Promise.resolve('Hello');
   
   p.then(function (s){
     console.log(s)
   });
   // Hello
   ```

4. 不带有任何参数

   > 返回一个`resolved`状态的 Promise 对象

**需要注意的是**，立即`resolve()`的 Promise 对象，是在本轮“事件循环”（event loop）的结束时执行，而不是在下一轮“事件循环”的开始时。

```javascript
setTimeout(function () {
  console.log('three');
}, 0);

Promise.resolve().then(function () {
  console.log('two');
});

console.log('one');

// one
// two
// three
```

上面代码中，`setTimeout(fn, 0)`在下一轮“事件循环”开始时执行，`Promise.resolve()`在本轮“事件循环”结束时执行，`console.log('one')`则是立即执行，因此最先输出。

### Promise.reject()

`Promise.reject(reason)`方法也会返回一个新的 Promise 实例，该实例的状态为`rejected`。

```javascript
const p = Promise.reject('出错了');
// 等同于
const p = new Promise((resolve, reject) => reject('出错了'))

p.then(null, function (s) {
  console.log(s)
});
// 出错了
```

注意，`Promise.reject()`方法的参数，会原封不动地作为`reject`的理由，变成后续方法的参数。这一点与`Promise.resolve`方法不一致。

```javascript
const thenable = {
  then(resolve, reject) {
    reject('出错了');
  }
};

Promise.reject(thenable)
.catch(e => {
  console.log(e === thenable)
})
// true
```

上面代码中，`Promise.reject`方法的参数是一个`thenable`对象，执行以后，后面`catch`方法的参数不是`reject`抛出的“出错了”这个字符串，而是`thenable`对象。

### Promise.try()

```javascript
function getUsername(userId) {
  return database.users.get({id: userId})
  .then(function(user) {
    return user.name;
  });
}
```

上面代码中，`database.users.get()`返回一个 Promise 对象，如果抛出异步错误，可以用`catch`方法捕获，就像下面这样写。

```javascript
database.users.get({id: userId})
.then(...)
.catch(...)
```

但是`database.users.get()`可能还会抛出同步错误（比如数据库连接错误，具体要看实现方法），这时你就不得不用`try...catch`去捕获。

```javascript
try {
  database.users.get({id: userId})
  .then(...)
  .catch(...)
} catch (e) {
  // ...
}
```

上面这样的写法就很笨拙了，这时就可以统一用`promise.catch()`捕获所有同步和异步的错误。

```javascript
Promise.try(() => database.users.get({id: userId}))
  .then(...)
  .catch(...)
```

事实上，`Promise.try`就是模拟`try`代码块，就像`promise.catch`模拟的是`catch`代码块。